Workbook

Sheet RELATORIO CONTROLADORIA
B1: COLABORADOR : | C1: Equipe | D1: RET. COM DESCONTO | E1: IND. 4% DO TOTAL | F1: RET. | G1: RETIRADA | H1: INSTALAÇÃO | I1: MANUTENÇÃO | J1: AT. | K1: P.V | L1: D.A. | M1: ATESTADO | N1: D.U | O1: D.C. | P1: MED. | Q1: valor | R1: Resultado
A2: Ind. Retrabalho | B2: COLABORADOR : | D2: 62 | E2: 249.8 | F2: 231 | G2: 52 | H2: 1253 | I2: 4940 | J2: 6245 | K2: 6183 | L2: 0 | M2: 0 | N2: 1459 | O2: 1649 | P2: 3.7 | Q2: 19474.1
A3: 0.0606 | B3: ALEFF PEREIRA SOARES | C3: INSTALAÇÃO | D3: 2 | E3: 3.96 | F3: 6 | H3: 42 | I3: 57 | J3: 99 | K3: 97 | N3: 24 | O3: 21 | P3: 4.62 | Q3: 351.84 | R3: Premio
A4: 0.0417 | B4: ALLYSSON DA SILVA MARINHO | C4: MISTO | D4: 0.2 | E4: 3.84 | F4: 4 | H4: 20 | I4: 76 | J4: 96 | K4: 95.8 | N4: 24 | O4: 23 | P4: 4.17 | Q4: 0 | R4: Premio não atingido
A5: 0.0488 | B5: ANDRE SILVA LOIOLA | C5: MISTO | D5: 0.7 | E5: 3.28 | F5: 4 | G5: 1 | H5: 5 | I5: 76 | J5: 82 | K5: 81.3 | N5: 24 | O5: 22 | P5: 3.69 | Q5: 0 | R5: Premio não atingido
A6: 0 | B6: ANTONIO CARLOS BARBOSA DE SOUSA | C6: JEBnet | D6: 0 | E6: 0.04 | I6: 1 | J6: 1 | K6: 1 | O6: 1 | P6: 1 | Q6: - | R6: -
A7: 0.0753 | B7: ANTONIO CARLOS FERREIRA DA SILVA | C7: INSTALAÇÃO | D7: 3.3 | E7: 3.72 | F7: 7 | G7: 2 | H7: 24 | I7: 67 | J7: 93 | K7: 89.7 | N7: 24 | O7: 20 | P7: 4.49 | Q7: 338.88 | R7: Premio
A8: 0.0506 | B8: ANTONIO EDUARDO TEIXEIRA CAMELO | C8: MISTO | D8: 0.8 | E8: 3.16 | F8: 4 | H8: 13 | I8: 66 | J8: 79 | K8: 78.2 | N8: 24 | O8: 21 | P8: 3.72 | Q8: 0 | R8: Premio não atingido
A9: 0 | B9: ANTONIO EUNARDES SOUSA BRAGA | C9: JEBnet | D9: 0 | E9: 3.28 | I9: 82 | J9: 82 | K9: 82 | O9: 25 | P9: 3.28 | Q9: - | R9: -
A10: 0.0408 | B10: ANTONIO FELIPE CASTRO DE OLIVEIRA | C10: MISTO COND. | D10: 0.1 | E10: 3.92 | F10: 4 | G10: 1 | H10: 31 | I10: 66 | J10: 98 | K10: 97.9 | N10: 24 | O10: 23 | P10: 4.26 | Q10: 669.68 | R10: Premio
A11: 0.0595 | B11: ANTONIO RAFAEL ALEXANDRE DE SOUSA | C11: MISTO | D11: 1.6 | E11: 3.36 | F11: 5 | H11: 20 | I11: 64 | J11: 84 | K11: 82.4 | N11: 24 | O11: 23 | P11: 3.58 | Q11: 0 | R11: Premio não atingido
A12: 0 | B12: ANTONIO TIAGO AMANCIO DA SILVA | C12: INSTALAÇÃO | D12: 0 | E12: 0.68 | G12: 2 | H12: 4 | I12: 11 | J12: 17 | K12: 17 | O12: 21 | P12: 0.81 | Q12: 51 | R12: Premio
A13: 0 | B13: ANTONIO WILSON SOARES DE SOUSA | C13: JEBnet | D13: 0 | E13: 3.96 | H13: 47 | I13: 52 | J13: 99 | K13: 99 | O13: 23 | P13: 4.3 | Q13: - | R13: -
A14: 0.0517 | B14: ARLISON DA SILVA PEREIRA | C14: MISTO | D14: 0.7 | E14: 2.32 | F14: 3 | H14: 7 | I14: 51 | J14: 58 | K14: 57.3 | N14: 24 | O14: 20 | P14: 2.87 | Q14: 0 | R14: Premio não atingido
A15: 0.0814 | B15: BRENDHOWN CESAR VIANA SILVA FALCAO | C15: MISTO COND. | D15: 3.6 | E15: 3.44 | F15: 7 | H15: 26 | I15: 60 | J15: 86 | K15: 82.4 | N15: 24 | O15: 21 | P15: 3.93 | Q15: 635.76 | R15: Premio
A16: 0.0556 | B16: BRUNO MATIAS DA SILVA | C16: MISTO | D16: 0.8 | E16: 2.16 | F16: 3 | H16: 15 | I16: 39 | J16: 54 | K16: 53.2 | N16: 24 | O16: 20 | P16: 2.66 | Q16: 0 | R16: Premio não atingido
A17: 0.0154 | B17: CAIO VICTOR MONTEIRO DE OLIVEIRA | C17: MISTO | D17: 0 | E17: 2.6 | F17: 1 | H17: 9 | I17: 56 | J17: 65 | K17: 65 | N17: 24 | O17: 21 | P17: 3.1 | Q17: 0 | R17: Premio não atingido
A18: 0.102 | B18: CARLOS HENRIQUE LINO SILVA | C18: MISTO COND. | D18: 6.1 | E18: 3.92 | F18: 10 | H18: 20 | I18: 78 | J18: 98 | K18: 91.9 | N18: 24 | O18: 19 | P18: 4.84 | Q18: 938.52 | R18: Premio
A19: 0.0645 | B19: CLAUDIANO CICINATO DA SILVA | C19: INSTALAÇÃO | D19: 1.5 | E19: 2.48 | F19: 4 | H19: 2 | I19: 60 | J19: 62 | K19: 60.5 | N19: 24 | O19: 15 | P19: 4.03 | Q19: 301.92 | R19: Premio
A20: 0.0189 | B20: DANILO OLIVEIRA DE SOUSA | C20: MISTO | D20: 0 | E20: 2.12 | F20: 1 | G20: 1 | H20: 9 | I20: 43 | J20: 53 | K20: 53 | O20: 23 | P20: 2.3 | Q20: 0 | R20: Premio não atingido
A21: 0.0326 | B21: DAVI MEDINA DE ARAUJO | C21: INSTALAÇÃO | D21: 0 | E21: 3.68 | F21: 3 | H21: 15 | I21: 77 | J21: 92 | K21: 92 | N21: 24 | O21: 20 | P21: 4.6 | Q21: 348 | R21: Premio
A22: 0.0635 | B22: DIEGO DA SILVA ASSUNCAO | C22: MISTO | D22: 1.5 | E22: 2.52 | F22: 4 | G22: 1 | H22: 12 | I22: 50 | J22: 63 | K22: 61.5 | O22: 23 | P22: 2.67 | Q22: 0 | R22: Premio não atingido
A23: 0.037 | B23: EDUARDO SANTOS DA SILVA | C23: GIGA | D23: 0 | E23: 1.08 | F23: 1 | H23: 3 | I23: 24 | J23: 27 | K23: 27 | O23: 23 | P23: 1.17 | Q23: 273.68 | R23: Premio
A24: 0.0417 | B24: ELISSON PEREIRA COUTINHO NOVAIS | C24: MISTO COND. | D24: 0.2 | E24: 3.84 | F24: 4 | H24: 23 | I24: 73 | J24: 96 | K24: 95.8 | N24: 24 | O24: 24 | P24: 3.99 | Q24: 647.36 | R24: Premio
A25: 0.0886 | B25: ELIZEU DA SILVA FERREIRA | C25: INSTALAÇÃO | D25: 3.8 | E25: 3.16 | F25: 7 | H25: 11 | I25: 68 | J25: 79 | K25: 75.2 | N25: 24 | O25: 23 | P25: 3.27 | Q25: 225.48 | R25: Premio
A26: 0.0112 | B26: EVERLAN DA PENHA TOME | C26: MISTO | D26: 0 | E26: 3.56 | F26: 1 | H26: 11 | I26: 78 | J26: 89 | K26: 89 | N26: 24 | O26: 20 | P26: 4.45 | Q26: 0 | R26: Premio não atingido
A27: 0.02 | B27: FELIPE MARTINS DAMASCENO | C27: INSTALAÇÃO | D27: 0 | E27: 2 | F27: 1 | H27: 19 | I27: 31 | J27: 50 | K27: 50 | N27: 24 | O27: 20 | P27: 2.5 | Q27: 150 | R27: Premio
A28: 0 | B28: FRANCISCO ANDERSON DA SILVA MORAIS | C28: Comercial | D28: 0 | E28: 0.32 | H28: 8 | J28: 8 | K28: 8 | O28: 21 | P28: 0.38 | Q28: - | R28: -
A29: 0.0411 | B29: FRANCISCO CARLOS EUGENIO DO NASCIMENTO | C29: MISTO | D29: 0.1 | E29: 2.92 | F29: 3 | H29: 15 | I29: 58 | J29: 73 | K29: 72.9 | N29: 24 | O29: 23 | P29: 3.17 | Q29: 0 | R29: Premio não atingido
A30: 0.0143 | B30: FRANCISCO DAS CHAGAS E SILVA ROCHA | C30: INSTALAÇÃO | D30: 0 | E30: 2.8 | F30: 1 | G30: 1 | H30: 8 | I30: 61 | J30: 70 | K30: 70 | N30: 24 | O30: 23 | P30: 3.04 | Q30: 210 | R30: Premio
A31: 0.0164 | B31: FRANCISCO DIEGO ALVES FERREIRA | C31: INSTALAÇÃO | D31: 0 | E31: 4.88 | F31: 2 | H31: 48 | I31: 74 | J31: 122 | K31: 122 | N31: 24 | O31: 23 | P31: 5.3 | Q31: 642 | R31: Premio
A32: 0.0187 | B32: FRANCISCO FELIPE DE LIMA ALVES | C32: MISTO | D32: 0 | E32: 4.28 | F32: 2 | G32: 2 | H32: 11 | I32: 94 | J32: 107 | K32: 107 | N32: 24 | O32: 23 | P32: 4.65 | Q32: 0 | R32: Premio não atingido
A33: 0.0079 | B33: FRANCISCO HELIO MARINHO CUNHA NETO | C33: INSTALAÇÃO | D33: 0 | E33: 5.08 | F33: 1 | G33: 2 | H33: 16 | I33: 109 | J33: 127 | K33: 127 | N33: 24 | O33: 22 | P33: 5.77 | Q33: 702 | R33: Premio
A34: 0.0353 | B34: FRANCISCO JHONATA DA COSTA | C34: MISTO | D34: 0 | E34: 3.4 | F34: 3 | H34: 13 | I34: 72 | J34: 85 | K34: 85 | N34: 24 | O34: 23 | P34: 3.7 | Q34: 0 | R34: Premio não atingido
A35: 0.0417 | B35: FRANCISCO LAERTE PEREIRA RODRIGUES | C35: - | D35: 0 | E35: 0.96 | F35: 1 | G35: 1 | H35: 7 | I35: 16 | J35: 24 | K35: 24 | N35: 24 | O35: 24 | P35: 1 | Q35: - | R35: -
A36: 0.0606 | B36: FRANCISCO MATHEUS PEREIRA MENDES | C36: INSTALAÇÃO | D36: 2 | E36: 3.96 | F36: 6 | H36: 13 | I36: 86 | J36: 99 | K36: 97 | N36: 24 | O36: 23 | P36: 4.22 | Q36: 319.84 | R36: Premio
A37: 0.0227 | B37: FRANCISCO TIAGO PINHEIRO | C37: MISTO | D37: 0 | E37: 3.52 | F37: 2 | H37: 9 | I37: 79 | J37: 88 | K37: 88 | N37: 24 | O37: 22 | P37: 4 | Q37: 0 | R37: Premio não atingido
A38: 0.0148 | B38: GABRIEL MARTINS MUNIZ | C38: INSTALAÇÃO | D38: 0 | E38: 5.4 | F38: 2 | G38: 4 | H38: 63 | I38: 68 | J38: 135 | K38: 135 | N38: 24 | O38: 18 | P38: 7.5 | Q38: 1290 | R38: Premio
A39: 0.0148 | B39: GEILSON DA SILVA MOURA | C39: MISTO COND. | D39: 0 | E39: 5.4 | F39: 2 | G39: 9 | H39: 35 | I39: 91 | J39: 135 | K39: 135 | N39: 24 | O39: 24 | P39: 5.63 | Q39: 1224 | R39: Premio
A40: 0.0229 | B40: GILVAN ASSUNCAO SILVA | C40: MISTO | D40: 0 | E40: 5.24 | F40: 3 | H40: 14 | I40: 117 | J40: 131 | K40: 131 | N40: 24 | O40: 16 | P40: 8.19 | Q40: 1230 | R40: Premio
...

Sheet FDT
A1: WA.ME/55 | B1: 959 | D1: 68 | E1: WA.ME/55 | F1: 959
A2: CONTATO WPP | B2: WHATSAPP | D2: TECNICO | E2: CONTATO WPP | F2: WHATSAPP | H2: CPF
C3: #N/A | G3: =C3 -> #N/A | H3: =IFERROR(VLOOKUP(D3,CPF!A:D,4,0),"NAO ENCONTRADO") -> NAO ENCONTRADO
A4: 85991012568 | B4: =CONCATENATE($A$1,A4) -> WA.ME/5585991012568 | C4: ALAN SOUTO | D4: ALAN FEITOSA DE SOUTO | E4: 85991012568 | F4: =CONCATENATE($E$1,E4) -> WA.ME/5585991012568 | G4: =C4 -> ALAN SOUTO | H4: =IFERROR(VLOOKUP(D4,CPF!A:D,4,0),"NAO ENCONTRADO") -> 0
B5: =CONCATENATE($A$1,A5) -> WA.ME/55 | C5: ALAN SOUTO | D5: ANTONIO TIAGO AMANCIO DA SILVA | F5: =CONCATENATE($E$1,E5) -> WA.ME/55 | G5: =C5 -> ALAN SOUTO | H5: =IFERROR(VLOOKUP(D5,CPF!A:D,4,0),"NAO ENCONTRADO") -> NAO ENCONTRADO
B6: =CONCATENATE($A$1,A6) -> WA.ME/55 | C6: ALAN SOUTO | D6: FRANCISCO LAERTE PEREIRA RODRIGUES | F6: =CONCATENATE($E$1,E6) -> WA.ME/55 | G6: =C6 -> ALAN SOUTO | H6: =IFERROR(VLOOKUP(D6,CPF!A:D,4,0),"NAO ENCONTRADO") -> NAO ENCONTRADO
B7: =CONCATENATE($A$1,A7) -> WA.ME/55 | C7: ALAN SOUTO | D7: JOAO PAULO DA SILVA LIMA | F7: =CONCATENATE($E$1,E7) -> WA.ME/55 | G7: =C7 -> ALAN SOUTO | H7: =IFERROR(VLOOKUP(D7,CPF!A:D,4,0),"NAO ENCONTRADO") -> 001.058.623-71
B8: =CONCATENATE($A$1,A8) -> WA.ME/55 | C8: ALAN SOUTO | D8: JOSE MARIA DA COSTA LEONARDO | F8: =CONCATENATE($E$1,E8) -> WA.ME/55 | G8: =C8 -> ALAN SOUTO | H8: =IFERROR(VLOOKUP(D8,CPF!A:D,4,0),"NAO ENCONTRADO") -> 734.146.113-68
B9: =CONCATENATE($A$1,A9) -> WA.ME/55 | C9: ALAN SOUTO | D9: KELTON CLEMENTE DOS SANTOS | F9: =CONCATENATE($E$1,E9) -> WA.ME/55 | G9: =C9 -> ALAN SOUTO | H9: =IFERROR(VLOOKUP(D9,CPF!A:D,4,0),"NAO ENCONTRADO") -> 013.487.253-38
B10: =CONCATENATE($A$1,A10) -> WA.ME/55 | C10: ALAN SOUTO | D10: LUIZ OCTAVIO ALMEIDA DA SILVA | F10: =CONCATENATE($E$1,E10) -> WA.ME/55 | G10: =C10 -> ALAN SOUTO | H10: =IFERROR(VLOOKUP(D10,CPF!A:D,4,0),"NAO ENCONTRADO") -> 087.399.743-32
B11: =CONCATENATE($A$1,A11) -> WA.ME/55 | C11: ALAN SOUTO | D11: MAILSON FRANCISCO PEREIRA | F11: =CONCATENATE($E$1,E11) -> WA.ME/55 | G11: =C11 -> ALAN SOUTO | H11: =IFERROR(VLOOKUP(D11,CPF!A:D,4,0),"NAO ENCONTRADO") -> 062.780.033-50
B12: =CONCATENATE($A$1,A12) -> WA.ME/55 | C12: ALAN SOUTO | D12: MARCOS VICTOR LOPES MEDEIROS FONSECA | F12: =CONCATENATE($E$1,E12) -> WA.ME/55 | G12: =C12 -> ALAN SOUTO | H12: =IFERROR(VLOOKUP(D12,CPF!A:D,4,0),"NAO ENCONTRADO") -> 034.029.363-21
B13: =CONCATENATE($A$1,A13) -> WA.ME/55 | C13: ALAN SOUTO | D13: WILLIAM ADRIANO DANTAS | F13: =CONCATENATE($E$1,E13) -> WA.ME/55 | G13: =C13 -> ALAN SOUTO | H13: =IFERROR(VLOOKUP(D13,CPF!A:D,4,0),"NAO ENCONTRADO") -> 070.038.853-28
B14: =CONCATENATE($A$1,A14) -> WA.ME/55 | C14: ALAN SOUTO | F14: =CONCATENATE($E$1,E14) -> WA.ME/55 | G14: =C14 -> ALAN SOUTO | H14: =IFERROR(VLOOKUP(D14,CPF!A:D,4,0),"NAO ENCONTRADO") -> NAO ENCONTRADO
B15: =CONCATENATE($A$1,A15) -> WA.ME/55 | C15: ALAN SOUTO | F15: =CONCATENATE($E$1,E15) -> WA.ME/55 | G15: =C15 -> ALAN SOUTO | H15: =IFERROR(VLOOKUP(D15,CPF!A:D,4,0),"NAO ENCONTRADO") -> NAO ENCONTRADO
B16: =CONCATENATE($A$1,A16) -> WA.ME/55 | C16: ALAN SOUTO | F16: =CONCATENATE($E$1,E16) -> WA.ME/55 | G16: =C16 -> ALAN SOUTO | H16: =IFERROR(VLOOKUP(D16,CPF!A:D,4,0),"NAO ENCONTRADO") -> NAO ENCONTRADO
B17: =CONCATENATE($A$1,A17) -> WA.ME/55 | C17: ALAN SOUTO | F17: =CONCATENATE($E$1,E17) -> WA.ME/55 | G17: =C17 -> ALAN SOUTO | H17: =IFERROR(VLOOKUP(D17,CPF!A:D,4,0),"NAO ENCONTRADO") -> NAO ENCONTRADO
B18: =CONCATENATE($A$1,A18) -> WA.ME/55 | C18: ALAN SOUTO | F18: =CONCATENATE($E$1,E18) -> WA.ME/55 | G18: =C18 -> ALAN SOUTO | H18: =IFERROR(VLOOKUP(D18,CPF!A:D,4,0),"NAO ENCONTRADO") -> NAO ENCONTRADO
B19: =CONCATENATE($A$1,A19) -> WA.ME/55 | C19: JEBNET | D19: ANTONIO CARLOS BARBOSA SOUSA | F19: =CONCATENATE($E$1,E19) -> WA.ME/55 | G19: =C19 -> JEBNET | H19: =IFERROR(VLOOKUP(D19,CPF!A:D,4,0),"NAO ENCONTRADO") -> NAO ENCONTRADO
B20: =CONCATENATE($A$1,A20) -> WA.ME/55 | C20: JEBNET | D20: ANTONIO EUNARDES SOUSA BRAGA | F20: =CONCATENATE($E$1,E20) -> WA.ME/55 | G20: =C20 -> JEBNET | H20: =IFERROR(VLOOKUP(D20,CPF!A:D,4,0),"NAO ENCONTRADO") -> NAO ENCONTRADO
B21: =CONCATENATE($A$1,A21) -> WA.ME/55 | C21: JEBNET | D21: ANTONIO WILSON SOARES DE SOUSA | F21: =CONCATENATE($E$1,E21) -> WA.ME/55 | G21: =C21 -> JEBNET | H21: =IFERROR(VLOOKUP(D21,CPF!A:D,4,0),"NAO ENCONTRADO") -> NAO ENCONTRADO
B22: =CONCATENATE($A$1,A22) -> WA.ME/55 | C22: JEBNET | D22: EMANUEL ALBANO GOMES | F22: =CONCATENATE($E$1,E22) -> WA.ME/55 | G22: =C22 -> JEBNET | H22: =IFERROR(VLOOKUP(D22,CPF!A:D,4,0),"NAO ENCONTRADO") -> NAO ENCONTRADO
B23: =CONCATENATE($A$1,A23) -> WA.ME/55 | C23: JEBNET | D23: FRANCISCO DA SILVA RODRIGUES | F23: =CONCATENATE($E$1,E23) -> WA.ME/55 | G23: =C23 -> JEBNET | H23: =IFERROR(VLOOKUP(D23,CPF!A:D,4,0),"NAO ENCONTRADO") -> NAO ENCONTRADO
B24: =CONCATENATE($A$1,A24) -> WA.ME/55 | C24: JEBNET | D24: FRANCISCO JOSE FREITAS NEO | F24: =CONCATENATE($E$1,E24) -> WA.ME/55 | G24: =C24 -> JEBNET | H24: =IFERROR(VLOOKUP(D24,CPF!A:D,4,0),"NAO ENCONTRADO") -> NAO ENCONTRADO
B25: =CONCATENATE($A$1,A25) -> WA.ME/55 | C25: JEBNET | D25: FRANCISCO RAFAEL DIAS | F25: =CONCATENATE($E$1,E25) -> WA.ME/55 | G25: =C25 -> JEBNET | H25: =IFERROR(VLOOKUP(D25,CPF!A:D,4,0),"NAO ENCONTRADO") -> NAO ENCONTRADO
B26: =CONCATENATE($A$1,A26) -> WA.ME/55 | C26: JEBNET | D26: FRANCISCO YURI DA COSTA MARTINS | F26: =CONCATENATE($E$1,E26) -> WA.ME/55 | G26: =C26 -> JEBNET | H26: =IFERROR(VLOOKUP(D26,CPF!A:D,4,0),"NAO ENCONTRADO") -> NAO ENCONTRADO
B27: =CONCATENATE($A$1,A27) -> WA.ME/55 | C27: JEBNET | D27: JOAO ADAILSON GOMES ALBANO | F27: =CONCATENATE($E$1,E27) -> WA.ME/55 | G27: =C27 -> JEBNET | H27: =IFERROR(VLOOKUP(D27,CPF!A:D,4,0),"NAO ENCONTRADO") -> NAO ENCONTRADO
B28: =CONCATENATE($A$1,A28) -> WA.ME/55 | C28: JEBNET | D28: JOAO BATISTA COELHO GOMES | F28: =CONCATENATE($E$1,E28) -> WA.ME/55 | G28: =C28 -> JEBNET | H28: =IFERROR(VLOOKUP(D28,CPF!A:D,4,0),"NAO ENCONTRADO") -> NAO ENCONTRADO
B29: =CONCATENATE($A$1,A29) -> WA.ME/55 | C29: JEBNET | D29: MICHEL PLATINI CORREIA MORAIS | F29: =CONCATENATE($E$1,E29) -> WA.ME/55 | G29: =C29 -> JEBNET | H29: =IFERROR(VLOOKUP(D29,CPF!A:D,4,0),"NAO ENCONTRADO") -> NAO ENCONTRADO
B30: =CONCATENATE($A$1,A30) -> WA.ME/55 | C30: JEBNET | D30: MILTON FERREIRA DE CASTRO | F30: =CONCATENATE($E$1,E30) -> WA.ME/55 | G30: =C30 -> JEBNET | H30: =IFERROR(VLOOKUP(D30,CPF!A:D,4,0),"NAO ENCONTRADO") -> NAO ENCONTRADO
... B32: =CONCATENATE($A$1,A32) -> WA.ME/55 | C32: JEBNET | D32: SERGIO MOURA PINTO | F32: =CONCATENATE($E$1,E32) -> WA.ME/55 | G32: =C32 -> JEBNET | H32: =IFERROR(VLOOKUP(D32,CPF!A:D,4,0),"NAO ENCONTRADO") -> NAO ENCONTRADO
A33: 85991012568 | B33: =CONCATENATE($A$1,A33) -> WA.ME/5585991012568 | C33: JOSE LEONARDO | D33: ALLYSSON DA SILVA MARINHO | E33: 85991012568 | F33: =CONCATENATE($E$1,E33) -> WA.ME/5585991012568 | G33: =C33 -> JOSE LEONARDO | H33: =IFERROR(VLOOKUP(D33,CPF!A:D,4,0),"NAO ENCONTRADO") -> 088.824.123-26
B34: =CONCATENATE($A$1,A34) -> WA.ME/55 | C34: JOSE LEONARDO | D34: CRISLANDO SANTOS DA SILVA | F34: =CONCATENATE($E$1,E34) -> WA.ME/55 | G34: =C34 -> JOSE LEONARDO | H34: =IFERROR(VLOOKUP(D34,CPF!A:D,4,0),"NAO ENCONTRADO") -> NAO ENCONTRADO
B35: =CONCATENATE($A$1,A35) -> WA.ME/55 | C35: JOSE LEONARDO | D35: FRANCISCO CARLOS EUGENIO DO NASCIMENTO | F35: =CONCATENATE($E$1,E35) -> WA.ME/55 | G35: =C35 -> JOSE LEONARDO | H35: =IFERROR(VLOOKUP(D35,CPF!A:D,4,0),"NAO ENCONTRADO") -> 045.179.853-85
B36: =CONCATENATE($A$1,A36) -> WA.ME/55 | C36: JOSE LEONARDO | D36: FRANCISCO HELIO MARINHO CUNHA NETO | F36: =CONCATENATE($E$1,E36) -> WA.ME/55 | G36: =C36 -> JOSE LEONARDO | H36: =IFERROR(VLOOKUP(D36,CPF!A:D,4,0),"NAO ENCONTRADO") -> 078.519.483-55
B37: =CONCATENATE($A$1,A37) -> WA.ME/55 | C37: JOSE LEONARDO | D37: FRANCISCO MATHEUS PEREIRA MENDES | F37: =CONCATENATE($E$1,E37) -> WA.ME/55 | G37: =C37 -> JOSE LEONARDO | H37: =IFERROR(VLOOKUP(D37,CPF!A:D,4,0),"NAO ENCONTRADO") -> 082.775.843-00
B38: =CONCATENATE($A$1,A38) -> WA.ME/55 | C38: JOSE LEONARDO | D38: FRANCISCO TIAGO PINHEIRO | F38: =CONCATENATE($E$1,E38) -> WA.ME/55 | G38: =C38 -> JOSE LEONARDO | H38: =IFERROR(VLOOKUP(D38,CPF!A:D,4,0),"NAO ENCONTRADO") -> 041.037.803-80
B39: =CONCATENATE($A$1,A39) -> WA.ME/55 | C39: JOSE LEONARDO | D39: GABRIEL MARTINS MUNIZ | F39: =CONCATENATE($E$1,E39) -> WA.ME/55 | G39: =C39 -> JOSE LEONARDO | H39: =IFERROR(VLOOKUP(D39,CPF!A:D,4,0),"NAO ENCONTRADO") -> 078.282.793-45
B40: =CONCATENATE($A$1,A40) -> WA.ME/55 | C40: JOSE LEONARDO | D40: GABRIEL MUNIZ DA COSTA | E40: 85981012568 | F40: =CONCATENATE($E$1,E40) -> WA.ME/5585981012568 | G40: =C40 -> JOSE LEONARDO | H40: 0
B41: =CONCATENATE($A$1,A41) -> WA.ME/55 | C41: JOSE LEONARDO | D41: GILVAN ASSUNCAO SILVA | F41: =CONCATENATE($E$1,E41) -> WA.ME/55 | G41: =C41 -> JOSE LEONARDO | H41: =IFERROR(VLOOKUP(D41,CPF!A:D,4,0),"NAO ENCONTRADO") -> 019.738.393-93
...

Sheet TABELA DE METAS
F1: DIAS TRABALHADOS
B2: Premiação | C2: VALOR | D2: META/DIA | E2: AE | F2: 31 | G2: 30 | H2: 29 | I2: 28 | J2: 27 | K2: 26 | L2: 25 | M2: 24 | N2: 23 | O2: 22 | P2: 21 | Q2: 20 | R2: 19 | S2: 18 | T2: 17 | U2: 16 | V2: 15 | W2: 14 | X2: 13 | Y2: 12 | Z2: 11
A3: MISTO | B3: PRATA | C3: 300 | D3: 5 | E3: 4 | F3: 155 | G3: 150 | H3: 145 | I3: 140 | J3: 135 | K3: 130 | L3: 125 | M3: 120 | N3: 115 | O3: 110 | P3: 105 | Q3: 100 | R3: 95 | S3: 90 | T3: 85 | U3: 80 | V3: 75 | W3: 70 | X3: 65 | Y3: 60 | Z3: 55
A4: MISTO | B4: OURO | C4: 600 | D4: 6 | E4: 6 | F4: 186 | G4: 180 | H4: 174 | I4: 168 | J4: 162 | K4: 156 | L4: 150 | M4: 144 | N4: 138 | O4: 132 | P4: 126 | Q4: 120 | R4: 114 | S4: 108 | T4: 102 | U4: 96 | V4: 90 | W4: 84 | X4: 78 | Y4: 72 | Z4: 66
A5: MISTO | B5: PLATINA | C5: 900 | D5: 7 | E5: 8 | F5: 217 | G5: 210 | H5: 203 | I5: 196 | J5: 189 | K5: 182 | L5: 175 | M5: 168 | N5: 161 | O5: 154 | P5: 147 | Q5: 140 | R5: 133 | S5: 126 | T5: 119 | U5: 112 | V5: 105 | W5: 98 | X5: 91 | Y5: 84 | Z5: 77
A6: MISTO | B6: DIAMANTE | C6: 1200 | D6: 8 | E6: 10 | F6: 248 | G6: 240 | H6: 232 | I6: 224 | J6: 216 | K6: 208 | L6: 200 | M6: 192 | N6: 184 | O6: 176 | P6: 168 | Q6: 160 | R6: 152 | S6: 144 | T6: 136 | U6: 128 | V6: 120 | W6: 112 | X6: 104 | Y6: 96 | Z6: 88
A7: PENDENCIA | B7: PRATA | C7: 300 | D7: 6 | E7: 4 | F7: 186 | G7: 180 | H7: 174 | I7: 168 | J7: 162 | K7: 156 | L7: 150 | M7: 144 | N7: 138 | O7: 132 | P7: 126 | Q7: 120 | R7: 114 | S7: 108 | T7: 102 | U7: 96 | V7: 90 | W7: 84 | X7: 78 | Y7: 72 | Z7: 66
A8: PENDENCIA | B8: OURO | C8: 600 | D8: 7 | E8: 6 | F8: 217 | G8: 210 | H8: 203 | I8: 196 | J8: 189 | K8: 182 | L8: 175 | M8: 168 | N8: 161 | O8: 154 | P8: 147 | Q8: 140 | R8: 133 | S8: 126 | T8: 119 | U8: 112 | V8: 105 | W8: 98 | X8: 91 | Y8: 84 | Z8: 77
A9: PENDENCIA | B9: PLATINA | C9: 900 | D9: 8 | E9: 8 | F9: 248 | G9: 240 | H9: 232 | I9: 224 | J9: 216 | K9: 208 | L9: 200 | M9: 192 | N9: 184 | O9: 176 | P9: 168 | Q9: 160 | R9: 152 | S9: 144 | T9: 136 | U9: 128 | V9: 120 | W9: 112 | X9: 104 | Y9: 96 | Z9: 88
A10: PENDENCIA | B10: DIAMANTE | C10: 1200 | D10: 9 | E10: 10 | F10: 279 | G10: 270 | H10: 261 | I10: 252 | J10: 243 | K10: 234 | L10: 225 | M10: 216 | N10: 207 | O10: 198 | P10: 189 | Q10: 180 | R10: 171 | S10: 162 | T10: 153 | U10: 144 | V10: 135 | W10: 126 | X10: 117 | Y10: 108 | Z10: 99
A11: MISTO COND. | B11: PRATA | C11: 600 | D11: 3.5 | E11: 4 | F11: 108.5 | G11: 105 | H11: 101.5 | I11: 98 | J11: 94.5 | K11: 91 | L11: 87.5 | M11: 84 | N11: 80.5 | O11: 77 | P11: 73.5 | Q11: 70 | R11: 66.5 | S11: 63 | T11: 59.5 | U11: 56 | V11: 52.5 | W11: 49 | X11: 45.5 | Y11: 42 | Z11: 38.5
A12: MISTO COND. | B12: OURO | C12: 900 | D12: 4.5 | E12: 6 | F12: 139.5 | G12: 135 | H12: 130.5 | I12: 126 | J12: 121.5 | K12: 117 | L12: 112.5 | M12: 108 | N12: 103.5 | O12: 99 | P12: 94.5 | Q12: 90 | R12: 85.5 | S12: 81 | T12: 76.5 | U12: 72 | V12: 67.5 | W12: 63 | X12: 58.5 | Y12: 54 | Z12: 49.5
A13: MISTO COND. | B13: PLATINA | C13: 1200 | D13: 5.5 | E13: 8 | F13: 170.5 | G13: 165 | H13: 159.5 | I13: 154 | J13: 148.5 | K13: 143 | L13: 137.5 | M13: 132 | N13: 126.5 | O13: 121 | P13: 115.5 | Q13: 110 | R13: 104.5 | S13: 99 | T13: 93.5 | U13: 88 | V13: 82.5 | W13: 77 | X13: 71.5 | Y13: 66 | Z13: 60.5
A14: MISTO COND. | B14: DIAMANTE | C14: 1500 | D14: 6.5 | E14: 10 | F14: 201.5 | G14: 195 | H14: 188.5 | I14: 182 | J14: 175.5 | K14: 169 | L14: 162.5 | M14: 156 | N14: 149.5 | O14: 143 | P14: 136.5 | Q14: 130 | R14: 123.5 | S14: 117 | T14: 110.5 | U14: 104 | V14: 97.5 | W14: 91 | X14: 84.5 | Y14: 78 | Z14: 71.5
... A26: PEND. COND. | B26: DIAMANTE | C26: 1500 | D26: 7.5 | E26: 10 | F26: 232.5 | G26: 225 | H26: 217.5 | I26: 210 | J26: 202.5 | K26: 195 | L26: 187.5 | M26: 180 | N26: 172.5 | O26: 165 | P26: 157.5 | Q26: 150 | R26: 142.5 | S26: 135 | T26: 127.5 | U26: 120 | V26: 112.5 | W26: 105 | X26: 97.5 | Y26: 90 | Z26: 82.5

Sheet CPF
A2: Nome | B2: Matrícula | C2: Empresa | D2: Cpf
A3: ALAN FEITOSA DE SOUTO | B3: 000262 | C3: G INFO
A4: ANTONIO MARCOS LIMA DA SILVA | C4: G INFO | D4: 009.280.143-98
A5: BRUNO MATIAS DA SILVA | C5: G INFO | D5: 070.863.133-94
A6: CLAUDIANO CICINATO DA SILVA | C6: G INFO | D6: 026.126.893-70
A7: DJONATHA COSTA DA SILVA | C7: G INFO | D7: 112.311.524-94
A8: ELISANGELA BOTELHO DA ROCHA | C8: G INFO | D8: 664.730.393-68
A9: ELISSON PEREIRA COUTINHO NOVAIS | C9: G INFO | D9: 078.114.013-71
A10: FABIO SILVESTRE BRITO | B10: 000115 | C10: G INFO | D10: 002.590.223-73
A11: FRANCISCO CARLOS EUGENIO DO NASCIMENTO | B11: 000333 | C11: G INFO | D11: 045.179.853-85
A12: FRANCISCO DAS CHAGAS E SILVA ROCHA | B12: 000216 | C12: G INFO | D12: 604.677.683-07
A13: FRANCISCO DIEGO ALVES FERREIRA | B13: 000295 | C13: G INFO | D13: 065.966.543-38
A14: FRANCISCO HELIO MARINHO CUNHA NETO | C14: G INFO | D14: 078.519.483-55
A15: FRANCISCO LUCAS SOUSA CUNHA | B15: 000305 | C15: G INFO | D15: 625.648.953-52
A16: GABRIEL MARTINS MUNIZ | B16: 000318 | C16: G INFO | D16: 078.282.793-45
A17: GEILSON DA SILVA MOURA | C17: G INFO | D17: 070.629.143-39
A18: GILVAN ASSUNCAO SILVA | B18: 000343 | C18: G INFO | D18: 019.738.393-93
A19: GLEISON VALENTIM ARAUJO | C19: G INFO | D19: 075.630.503-96
A20: GUTEMBERGUE OLIVEIRA | B20: 000271 | C20: G INFO | D20: 020.305.163-76
A21: HALLEF GUILHERME LIMA CLEMENTE SILVA | C21: G INFO | D21: 077.115.853-06
A22: IRINETO FERREIRA DE AGUIAR | B22: 000217 | C22: G INFO | D22: 033.727.593-97
A23: JOAO PAULO GOUVEIA DA SILVA | C23: G INFO | D23: 891.107.223-00
A24: JOSE AMAURY BORGES FILHO | C24: G INFO | D24: 068.959.103-95
A25: JOSE MARIA DA COSTA LEONARDO | B25: 000221 | C25: G INFO | D25: 734.146.113-68
A26: LUCAS SOUZA SILVA | C26: G INFO | D26: 074.800.793-89
A27: LUCIEUDO BANDEIRA ALVES FILHO | B27: 000320 | C27: G INFO | D27: 074.418.063-56
A28: LUIZ CARLOS MACHADO MACIEL | C28: G INFO | D28: 058.715.743-78
A29: MAILSON FRANCISCO PEREIRA | C29: G INFO | D29: 062.780.033-50
A30: MARCOS PEREIRA CARVALHO FILHO | C30: G INFO | D30: 073.501.783-28
A31: MARCOS VICTOR LOPES MEDEIROS FONSECA | C31: G INFO | D31: 034.029.363-21
A32: PAULO ROBERTO ARAUJO GALVAO | C32: G INFO | D32: 014.069.373-47
A33: PEDRO DA SILVA MAIA | C33: G INFO | D33: 092.106.483-74
A34: ROBSON BEZERRA DA SILVA | C34: G INFO | D34: 619.340.993-92
A35: ROMARIO NOBRE DE MELO | B35: 000336 | C35: G INFO | D35: 051.728.733-17
A36: RONALD MESQUITA DOS SANTOS | C36: G INFO | D36: 107.099.153-81
A37: THIAGO CASTRO DO NASCIMENTO | C37: G INFO | D37: 086.965.763-14
A38: VALDERILO FERREIRA LIMA JUNIOR | B38: 000293 | C38: G INFO | D38: 082.974.113-54
A40: WILLIAM ADRIANO DANTAS | B40: 000116 | C40: G INFO | D40: 070.038.853-28
A41: YVINA CHAGAS ALENCAR | C41: G INFO | D41: 080.135.683-00
A42: ALEFF PEREIRA SOARES | C42: IFT | D42: 068.984.563-42
...
